Workbook

Sheet classFile
A1: Class | B1: Sales TY ($) | C1: Sales LY ($) | D1: Sales 2LY ($) | E1: Var LY ($) | F1: Var 2LY ($) | G1: % Var LY ($) | H1: % Var 2LY ($) | I1: Sales TY (Units) | J1: Sales LY (Units) | K1: Sales 2LY (Units) | L1: Var LY (Units) | M1: Var 2LY (Units) | N1: % Var LY (Units) | O1: % Var 2LY (Units) | P1: Sales TY (ATV) | Q1: Sales LY (ATV) | R1: Sales 2LY (ATV) | S1: Var LY (ATV) | T1: Var 2LY(ATV) | U1: % Var LY (ATV) | V1: % Var 2LY (ATV) | W1: % Margin TY | X1: % Margin LY | Y1: % Margin 2LY | Z1: % Var LY (Margin) | AA1: % Var 2LY (Margin)
A2: MEDIA PLAYER | B2: 32423.059 | C2: 0 | D2: 0 | E2: 32423.059 | F2: 32423.059 | I2: 878 | J2: 0 | K2: 0 | L2: 878 | M2: 878 | P2: 36.928313 | W2: 0.23787935 | Z2: inf | AA2: inf
A3: TV 32INCH | B3: 559407.64 | C3: 0 | D3: 0 | E3: 559407.64 | F3: 559407.64 | I3: 2833 | J3: 0 | K3: 0 | L3: 2833 | M3: 2833 | P3: 197.46122 | W3: 0.29452692 | Z3: inf | AA3: inf
A4: TV 43INCH LT | B4: 615310.47 | C4: 0 | D4: 0 | E4: 615310.47 | F4: 615310.47 | I4: 1767 | J4: 0 | K4: 0 | L4: 1767 | M4: 1767 | P4: 348.22324 | W4: 0.30147727 | Z4: inf | AA4: inf
A5: TV 50INCH LT | B5: 856539.62 | C5: 0 | D5: 0 | E5: 856539.62 | F5: 856539.62 | I5: 1597 | J5: 0 | K5: 0 | L5: 1597 | M5: 1597 | P5: 536.34291 | W5: 0.21795541 | Z5: inf | AA5: inf
A6: TV 55INCH LT | B6: 227399.15 | C6: 0 | D6: 0 | E6: 227399.15 | F6: 227399.15 | I6: 253 | J6: 0 | K6: 0 | L6: 253 | M6: 253 | P6: 898.81086 | W6: 0.46546777 | Z6: inf | AA6: inf
A7: TV 65INCH GT | B7: 147664.88 | C7: 0 | D7: 0 | E7: 147664.88 | F7: 147664.88 | I7: 140 | J7: 0 | K7: 0 | L7: 140 | M7: 140 | P7: 1054.7491 | W7: 0.38999923 | Z7: inf | AA7: inf
A8: TV 75INCH LT | B8: 78625.941 | C8: 0 | D8: 0 | E8: 78625.941 | F8: 78625.941 | I8: 52 | J8: 0 | K8: 0 | L8: 52 | M8: 52 | P8: 1512.0373 | W8: 0.2525776 | Z8: inf | AA8: inf
A9: TV 85INCH GT | B9: 13549.428 | C9: 0 | D9: 0 | E9: 13549.428 | F9: 13549.428 | I9: 4 | J9: 0 | K9: 0 | L9: 4 | M9: 4 | P9: 3387.357 | W9: 0.17949256 | Z9: inf | AA9: inf
A10: VIDEO ACCESSORIES | B10: 1221.0835 | C10: 0 | D10: 0 | E10: 1221.0835 | F10: 1221.0835 | I10: 78 | J10: 0 | K10: 0 | L10: 78 | M10: 78 | P10: 15.654917 | W10: 0.37519046 | Z10: inf | AA10: inf
A11: Total | B11: 2532141.3 | C11: 0 | D11: 0 | E11: 2532141.3 | F11: 2532141.3 | I11: 7602 | J11: 0 | K11: 0 | L11: 7602 | M11: 7602 | P11: 333.08883 | W11: 0.28862861 | Z11: inf | AA11: inf
A13: Applied filters: Añofiscal is 2020 REGION is CAR COUNTRY is Trinidad and Tobago ENG_DIVISION is AUDIO VISUAL ENG_DEPARTMENT is VISION ENG_CLASS is not (Blank) or PREPAID BALANCE REGION is not ALL or USA COUNTRY is not Paraguay or Aruba
A15: Class | B15: Sales TY ($) | C15: Sales LY ($) | D15: Sales 2LY ($) | E15: Var LY ($) | F15: Var 2LY ($) | G15: % Var LY ($) | H15: % Var 2LY ($) | I15: Sales TY (Units) | J15: Sales LY (Units) | K15: Sales 2LY (Units) | L15: Var LY (Units) | M15: Var 2LY (Units) | N15: % Var LY (Units) | O15: % Var 2LY (Units) | P15: Sales TY (ATV) | Q15: Sales LY (ATV) | R15: Sales 2LY (ATV) | S15: Var LY (ATV) | T15: Var 2LY(ATV) | U15: % Var LY (ATV) | V15: % Var 2LY (ATV) | W15: % Margin TY | X15: % Margin LY | Y15: % Margin 2LY | Z15: % Var LY (Margin) | AA15: % Var 2LY (Margin)
A16: MEDIA PLAYER | B16: 102782.46 | C16: 32423.059 | D16: 0 | E16: 70359.405 | F16: 102782.46 | G16: 2.1700422 | I16: 2613 | J16: 878 | K16: 0 | L16: 1735 | M16: 2613 | N16: 1.976082 | P16: 39.335042 | Q16: 36.928313 | S16: 2.4067284 | U16: 0.065172986 | W16: 0.22645912 | X16: 0.23787935 | Z16: -0.048008493 | AA16: inf
A17: TV 32INCH | B17: 2268955 | C17: 559407.64 | D17: 0 | E17: 1709547.3 | F17: 2268955 | G17: 3.0559957 | I17: 11598 | J17: 2833 | K17: 0 | L17: 8765 | M17: 11598 | N17: 3.0938934 | P17: 195.6333 | Q17: 197.46122 | S17: -1.8279262 | U17: -0.00925714 | W17: 0.27965869 | X17: 0.29452692 | Z17: -0.050481728 | AA17: inf
A18: TV 43INCH LT | B18: 2884099.5 | C18: 615310.47 | D18: 0 | E18: 2268789 | F18: 2884099.5 | G18: 3.6872264 | I18: 9070 | J18: 1767 | K18: 0 | L18: 7303 | M18: 9070 | N18: 4.1329938 | P18: 317.9823 | Q18: 348.22324 | S18: -30.240941 | U18: -0.086843544 | W18: 0.27782168 | X18: 0.30147727 | Z18: -0.078465582 | AA18: inf
A19: TV 50INCH LT | B19: 3904348.4 | C19: 856539.62 | D19: 0 | E19: 3047808.8 | F19: 3904348.4 | G19: 3.5582812 | I19: 8110 | J19: 1597 | K19: 0 | L19: 6513 | M19: 8110 | N19: 4.0782718 | P19: 481.42397 | Q19: 536.34291 | S19: -54.918932 | U19: -0.10239519 | W19: 0.23185864 | X19: 0.21795541 | Z19: 0.063789326 | AA19: inf
A20: TV 55INCH LT | B20: 1924390.8 | C20: 227399.15 | D20: 0 | E20: 1696991.6 | F20: 1924390.8 | G20: 7.4626121 | I20: 3004 | J20: 253 | K20: 0 | L20: 2751 | M20: 3004 | N20: 10.873518 | P20: 640.60945 | Q20: 898.81086 | S20: -258.20141 | U20: -0.28727002 | W20: 0.37667812 | X20: 0.46546777 | Z20: -0.19075359 | AA20: inf
A21: TV 65INCH GT | B21: 1317365.5 | C21: 147664.88 | D21: 0 | E21: 1169700.6 | F21: 1317365.5 | G21: 7.9213191 | I21: 1495 | J21: 140 | K21: 0 | L21: 1355 | M21: 1495 | N21: 9.6785714 | P21: 881.18095 | Q21: 1054.7491 | S21: -173.56819 | U21: -0.16455874 | W21: 0.32392794 | X21: 0.38999923 | Z21: -0.16941391 | AA21: inf
A22: TV 75INCH LT | B22: 157662.46 | C22: 78625.941 | D22: 0 | E22: 79036.519 | F22: 157662.46 | G22: 1.0052219 | I22: 99 | J22: 52 | K22: 0 | L22: 47 | M22: 99 | N22: 0.90384615 | P22: 1592.5501 | Q22: 1512.0373 | S22: 80.512766 | U22: 0.053247869 | W22: 0.28000272 | X22: 0.2525776 | Z22: 0.10858098 | AA22: inf
A23: TV 85INCH GT | B23: 48861.51 | C23: 13549.428 | D23: 0 | E23: 35312.082 | F23: 48861.51 | G23: 2.6061678 | I23: 15 | J23: 4 | K23: 0 | L23: 11 | M23: 15 | N23: 2.75 | P23: 3257.434 | Q23: 3387.357 | S23: -129.92297 | U23: -0.038355265 | W23: 0.10289946 | X23: 0.17949256 | Z23: -0.4267202 | AA23: inf
A24: VIDEO ACCESSORIES | B24: 9598.3577 | C24: 1221.0835 | D24: 0 | E24: 8377.2742 | F24: 9598.3577 | G24: 6.8605253 | I24: 361 | J24: 78 | K24: 0 | L24: 283 | M24: 361 | N24: 3.6282051 | P24: 26.588248 | Q24: 15.654917 | S24: 10.933332 | U24: 0.69839604 | W24: 0.26032387 | X24: 0.37519046 | Z24: -0.30615541 | AA24: inf
A25: Total | B25: 12618064 | C25: 2532141.3 | D25: 0 | E25: 10085923 | F25: 12618064 | G25: 3.9831596 | I25: 36365 | J25: 7602 | K25: 0 | L25: 28763 | M25: 36365 | N25: 3.7836096 | P25: 346.98375 | Q25: 333.08883 | S25: 13.894919 | U25: 0.041715356 | W25: 0.28273839 | X25: 0.28862861 | Z25: -0.020407621 | AA25: inf
A27: Applied filters: Añofiscal is 2021 REGION is CAR COUNTRY is Trinidad and Tobago ENG_DIVISION is AUDIO VISUAL ENG_DEPARTMENT is VISION ENG_CLASS is not (Blank) or PREPAID BALANCE REGION is not ALL or USA COUNTRY is not Paraguay or Aruba
A29: Class | B29: Sales TY ($) | C29: Sales LY ($) | D29: Sales 2LY ($) | E29: Var LY ($) | F29: Var 2LY ($) | G29: % Var LY ($) | H29: % Var 2LY ($) | I29: Sales TY (Units) | J29: Sales LY (Units) | K29: Sales 2LY (Units) | L29: Var LY (Units) | M29: Var 2LY (Units) | N29: % Var LY (Units) | O29: % Var 2LY (Units) | P29: Sales TY (ATV) | Q29: Sales LY (ATV) | R29: Sales 2LY (ATV) | S29: Var LY (ATV) | T29: Var 2LY(ATV) | U29: % Var LY (ATV) | V29: % Var 2LY (ATV) | W29: % Margin TY | X29: % Margin LY | Y29: % Margin 2LY | Z29: % Var LY (Margin) | AA29: % Var 2LY (Margin)
A30: MEDIA PLAYER | B30: 14035.385 | C30: 102782.46 | D30: 32423.059 | E30: -88747.079 | F30: -18387.674 | G30: -0.86344572 | H30: -0.56711719 | I30: 516 | J30: 2613 | K30: 878 | L30: -2097 | M30: -362 | N30: -0.80252583 | O30: -0.41230068 | P30: 27.200358 | Q30: 39.335042 | R30: 36.928313 | S30: -12.134683 | T30: -9.727955 | U30: -0.3084955 | V30: -0.26342809 | W30: 0.20515999 | X30: 0.22645912 | Y30: 0.23787935 | Z30: -0.094052898 | AA30: -0.13754605
A31: TV 32INCH | B31: 2036266.6 | C31: 2268955 | D31: 559407.64 | E31: -232688.36 | F31: 1476859 | G31: -0.1025531 | H31: 2.6400407 | I31: 8162 | J31: 11598 | K31: 2833 | L31: -3436 | M31: 5329 | N31: -0.29625798 | O31: 1.8810448 | P31: 249.48133 | Q31: 195.6333 | R31: 197.46122 | S31: 53.848033 | T31: 52.020107 | U31: 0.27524984 | V31: 0.26344467 | W31: 0.13798503 | X31: 0.27965869 | Y31: 0.29452692 | Z31: -0.50659487 | AA31: -0.53150281
A32: TV 43INCH LT | B32: 2999027.1 | C32: 2884099.5 | D32: 615310.47 | E32: 114927.64 | F32: 2383716.7 | G32: 0.03984871 | H32: 3.8740063 | I32: 7614 | J32: 9070 | K32: 1767 | L32: -1456 | M32: 5847 | N32: -0.16052922 | O32: 3.3089983 | P32: 393.88326 | Q32: 317.9823 | R32: 348.22324 | S32: 75.900955 | T32: 45.660015 | U32: 0.23869553 | V32: 0.13112282 | W32: 0.12840255 | X32: 0.27782168 | Y32: 0.30147727 | Z32: -0.53782387 | AA32: -0.57408879
A33: TV 50INCH LT | B33: 2814518.5 | C33: 3904348.4 | D33: 856539.62 | E33: -1089829.9 | F33: 1957978.9 | G33: -0.27913234 | H33: 2.2859175 | I33: 4860 | J33: 8110 | K33: 1597 | L33: -3250 | M33: 3263 | N33: -0.40073983 | O33: 2.043206 | P33: 579.11903 | Q33: 481.42397 | R33: 536.34291 | S33: 97.695059 | T33: 42.776127 | U33: 0.20292936 | V33: 0.079755184 | W33: 0.10762079 | X33: 0.23185864 | Y33: 0.21795541 | Z33: -0.53583448 | AA33: -0.50622567
A34: TV 55INCH LT | B34: 2201233.5 | C34: 1924390.8 | D34: 227399.15 | E34: 276842.7 | F34: 1973834.3 | G34: 0.14385992 | H34: 8.6800428 | I34: 3355 | J34: 3004 | K34: 253 | L34: 351 | M34: 3102 | N34: 0.11684421 | O34: 12.26087 | P34: 656.10536 | Q34: 640.60945 | R34: 898.81086 | S34: 15.495911 | T34: -242.7055 | U34: 0.024189326 | V34: -0.27002956 | W34: 0.19605604 | X34: 0.37667812 | Y34: 0.46546777 | Z34: -0.47951308 | AA34: -0.57879783
A35: TV 65INCH GT | B35: 1528372.1 | C35: 1317365.5 | D35: 147664.88 | E35: 211006.55 | F35: 1380707.2 | G35: 0.16017312 | H35: 9.3502747 | I35: 1613 | J35: 1495 | K35: 140 | L35: 118 | M35: 1473 | N35: 0.078929766 | O35: 10.521429 | P35: 947.53383 | Q35: 881.18095 | R35: 1054.7491 | S35: 66.352882 | T35: -107.21531 | U35: 0.075299951 | V35: -0.10165006 | W35: 0.26497064 | X35: 0.32392794 | Y35: 0.38999923 | Z35: -0.18200744 | AA35: -0.32058676
A36: TV 75INCH LT | B36: 266992.75 | C36: 157662.46 | D36: 78625.941 | E36: 109330.29 | F36: 188366.81 | G36: 0.69344529 | H36: 2.3957336 | I36: 171 | J36: 99 | K36: 52 | L36: 72 | M36: 119 | N36: 0.72727273 | O36: 2.2884615 | P36: 1561.3611 | Q36: 1592.5501 | R36: 1512.0373 | S36: -31.188988 | T36: 49.323778 | U36: -0.019584306 | V36: 0.032620741 | W36: 0.32552754 | X36: 0.28000272 | Y36: 0.2525776 | Z36: 0.16258708 | AA36: 0.28882193
A37: TV 85INCH GT | B37: 12955.973 | C37: 48861.51 | D37: 13549.428 | E37: -35905.537 | F37: -593.45496 | G37: -0.73484297 | H37: -0.043799263 | I37: 4 | J37: 15 | K37: 4 | L37: -11 | M37: 0 | N37: -0.73333333 | O37: 0 | P37: 3238.9932 | Q37: 3257.434 | R37: 3387.357 | S37: -18.440766 | T37: -148.36374 | U37: -0.0056611326 | V37: -0.043799263 | W37: 0.15372428 | X37: 0.10289946 | Y37: 0.17949256 | Z37: 0.49392704 | AA37: -0.14356181
A38: VIDEO ACCESSORIES | B38: 443.49429 | C38: 9598.3577 | D38: 1221.0835 | E38: -9154.8634 | F38: -777.58921 | G38: -0.95379477 | H38: -0.63680265 | I38: 38 | J38: 361 | K38: 78 | L38: -323 | M38: -40 | N38: -0.89473684 | O38: -0.51282051 | P38: 11.670902 | Q38: 26.588248 | R38: 15.654917 | S38: -14.917346 | T38: -3.9840143 | U38: -0.56105035 | V38: -0.25448965 | W38: 0.30761339 | X38: 0.26032387 | Y38: 0.37519046 | Z38: 0.18165647 | AA38: -0.18011405
A39: Total | B39: 11873845 | C39: 12618064 | D39: 2532141.3 | E39: -744218.58 | F39: 9341704.1 | G39: -0.05898041 | H39: 3.6892508 | I39: 26333 | J39: 36365 | K39: 7602 | L39: -10032 | M39: 18731 | N39: -0.27586965 | O39: 2.4639569 | P39: 450.91123 | Q39: 346.98375 | R39: 333.08883 | S39: 103.92748 | T39: 117.8224 | U39: 0.29951686 | V39: 0.35372667 | W39: 0.15979808 | X39: 0.28273839 | Y39: 0.28862861 | Z39: -0.43482003 | AA39: -0.44635401
A41: Applied filters: Añofiscal is 2022 REGION is CAR COUNTRY is Trinidad and Tobago ENG_DIVISION is AUDIO VISUAL ENG_DEPARTMENT is VISION ENG_CLASS is not (Blank) or PREPAID BALANCE REGION is not ALL or USA COUNTRY is not Paraguay or Aruba
A43: Class | B43: Sales TY ($) | C43: Sales LY ($) | D43: Sales 2LY ($) | E43: Var LY ($) | F43: Var 2LY ($) | G43: % Var LY ($) | H43: % Var 2LY ($) | I43: Sales TY (Units) | J43: Sales LY (Units) | K43: Sales 2LY (Units) | L43: Var LY (Units) | M43: Var 2LY (Units) | N43: % Var LY (Units) | O43: % Var 2LY (Units) | P43: Sales TY (ATV) | Q43: Sales LY (ATV) | R43: Sales 2LY (ATV) | S43: Var LY (ATV) | T43: Var 2LY(ATV) | U43: % Var LY (ATV) | V43: % Var 2LY (ATV) | W43: % Margin TY | X43: % Margin LY | Y43: % Margin 2LY | Z43: % Var LY (Margin) | AA43: % Var 2LY (Margin)
A44: MEDIA PLAYER | B44: 8619.2829 | C44: 14035.385 | D44: 102782.46 | E44: -5416.1019 | F44: -94163.181 | G44: -0.38588909 | H44: -0.91614053 | I44: 411 | J44: 516 | K44: 2613 | L44: -105 | M44: -2202 | N44: -0.20348837 | O44: -0.84270953 | P44: 20.971491 | Q44: 27.200358 | R44: 39.335042 | S44: -6.2288668 | T44: -18.36355 | U44: -0.22899944 | V44: -0.46684965 | W44: 0.2454052 | X44: 0.20515999 | Y44: 0.22645912 | Z44: 0.19616503 | AA44: 0.083662242
A45: TV 32INCH | B45: 2013109.2 | C45: 2036266.6 | D45: 2268955 | E45: -23157.377 | F45: -255845.73 | G45: -0.011372468 | H45: -0.11275928 | I45: 8846 | J45: 8162 | K45: 11598 | L45: 684 | M45: -2752 | N45: 0.083802989 | O45: -0.23728229 | P45: 227.57283 | Q45: 249.48133 | R45: 195.6333 | S45: -21.908502 | T45: 31.939532 | U45: -0.087816198 | V45: 0.16326225 | W45: 0.16220652 | X45: 0.13798503 | Y45: 0.27965869 | Z45: 0.17553707 | AA45: -0.41998397
A46: TV 43INCH LT | B46: 3420765.2 | C46: 2999027.1 | D46: 2884099.5 | E46: 421738.12 | F46: 536665.76 | G46: 0.14062498 | H46: 0.18607741 | I46: 8501 | J46: 7614 | K46: 9070 | L46: 887 | M46: -569 | N46: 0.11649593 | O46: -0.062734289 | P46: 402.39563 | Q46: 393.88326 | R46: 317.9823 | S46: 8.5123713 | T46: 84.413327 | U46: 0.021611407 | V46: 0.26546549 | W46: 0.25177244 | X46: 0.12840255 | Y46: 0.27782168 | Z46: 0.96080559 | AA46: -0.093762467
...

Sheet ClassTrend
B1: {=TRANSPOSE(classFile!A2:A10)} -> MEDIA PLAYER | C1: TV 32INCH | D1: TV 43INCH LT | E1: TV 50INCH LT | F1: TV 55INCH LT | G1: TV 65INCH GT | H1: TV 75INCH LT | I1: TV 85INCH GT | J1: VIDEO ACCESSORIES | K1: TOTAL | N1: =B1 -> MEDIA PLAYER | O1: =C1 -> TV 32INCH | P1: =D1 -> TV 43INCH LT | Q1: =E1 -> TV 50INCH LT | R1: =F1 -> TV 55INCH LT | S1: =G1 -> TV 65INCH GT | T1: =H1 -> TV 75INCH LT | U1: =I1 -> TV 85INCH GT | V1: =J1 -> VIDEO ACCESSORIES
A2: AVERAGE | B2: =AVERAGE(B9:B14) -> 751.33333 | C2: =AVERAGE(C9:C14) -> 7984.1667 | D2: =AVERAGE(D9:D14) -> 6865.6667 | E2: =AVERAGE(E9:E14) -> 5920.5 | F2: =AVERAGE(F9:F14) -> 4637.8333 | G2: =AVERAGE(G9:G14) -> 1956.6667 | H2: =AVERAGE(H9:H14) -> 428.16667 | I2: =AVERAGE(I9:I14) -> 104.5 | ... K2: =AVERAGE(K9:K14) -> 28737.333 | M2: AVERAGE | N2: =+AVERAGE(N9:N14) -> 0.037099663 | O2: =+AVERAGE(O9:O14) -> 0.29141351 | P2: =+AVERAGE(P9:P14) -> 0.24044186 | Q2: =+AVERAGE(Q9:Q14) -> 0.20684806 | R2: =+AVERAGE(R9:R14) -> 0.14255878 | S2: =+AVERAGE(S9:S14) -> 0.061140215 | T2: =+AVERAGE(T9:T14) -> 0.013594265 | U2: =+AVERAGE(U9:U14) -> 0.0030261433 | V2: =+AVERAGE(V9:V14) -> 0.0038775068 | W2: =SUM(N2:V2) -> 1
B3: =B2/$K$2 -> 0.026144852 | C3: =C2/$K$2 -> 0.27783255 | D3: =D2/$K$2 -> 0.23891106 | E3: =E2/$K$2 -> 0.2060212 | F3: =F2/$K$2 -> 0.16138705 | G3: =G2/$K$2 -> 0.068087969 | H3: =H2/$K$2 -> 0.014899318 | I3: =I2/$K$2 -> 0.0036363847 | J3: =J2/$K$2 -> 0.0030796177 | K3: =SUM(B3:J3) -> 1
M4: MAX | N4: =MAX(N9:N14) -> 0.11549592 | O4: =MAX(O9:O14) -> 0.37266509 | P4: =MAX(P9:P14) -> 0.2891429 | Q4: =MAX(Q9:Q14) -> 0.25772635 | R4: =MAX(R9:R14) -> 0.2738469 | S4: =MAX(S9:S14) -> 0.10434946 | T4: =MAX(T9:T14) -> 0.025195613 | U4: =MAX(U9:U14) -> 0.0099278221 | V4: =MAX(V9:V14) -> 0.010260458
M5: MIN | N5: =MIN(N9:N14) -> 8.0495854e-05 | O5: =MIN(O9:O14) -> 0.23107677 | P5: =MIN(P9:P14) -> 0.19491858 | Q5: =MIN(Q9:Q14) -> 0.14728058 | R5: =MIN(R9:R14) -> 0.033280716 | S5: =MIN(S9:S14) -> 0.018416206 | T5: =MIN(T9:T14) -> 0.0027223979 | U5: =MIN(U9:U14) -> 0.00015190066 | V5: =MIN(V9:V14) -> 0.00024168454
N6: =AVERAGE(N4:N5) -> 0.057788209 | O6: =AVERAGE(O4:O5) -> 0.30187093 | P6: =AVERAGE(P4:P5) -> 0.24203074 | Q6: =AVERAGE(Q4:Q5) -> 0.20250347 | R6: =AVERAGE(R4:R5) -> 0.15356381 | S6: =AVERAGE(S4:S5) -> 0.061382833 | T6: =AVERAGE(T4:T5) -> 0.013959006 | U6: =AVERAGE(U4:U5) -> 0.0050398614 | V6: =AVERAGE(V4:V5) -> 0.0052510712
A8: YEAR | M8: YEAR
A9: 2020 | B9: {=TRANSPOSE(classFile!I2:I10)} -> 878 | C9: 2833 | D9: 1767 | E9: 1597 | F9: 253 | G9: 140 | H9: 52 | I9: 4 | J9: 78 | K9: =SUM(B9:J9) -> 7602 | M9: =A9 -> 2020 | N9: =B9/$K9 -> 0.11549592 | O9: =C9/$K9 -> 0.37266509 | P9: =D9/$K9 -> 0.23243883 | Q9: =E9/$K9 -> 0.2100763 | R9: =F9/$K9 -> 0.033280716 | S9: =G9/$K9 -> 0.018416206 | T9: =H9/$K9 -> 0.0068403052 | U9: =I9/$K9 -> 0.00052617732 | V9: =J9/$K9 -> 0.010260458 | W9: =SUM(N9:V9) -> 1
A10: 2021 | B10: {=TRANSPOSE(classFile!I16:I24)} -> 2613 | C10: 11598 | D10: 9070 | E10: 8110 | F10: 3004 | G10: 1495 | H10: 99 | I10: 15 | J10: 361 | K10: =SUM(B10:J10) -> 36365 | M10: =A10 -> 2021 | N10: =B10/$K10 -> 0.071854805 | O10: =C10/$K10 -> 0.31893304 | P10: =D10/$K10 -> 0.24941565 | Q10: =E10/$K10 -> 0.22301664 | R10: =F10/$K10 -> 0.082606902 | S10: =G10/$K10 -> 0.041110958 | T10: =H10/$K10 -> 0.0027223979 | U10: =I10/$K10 -> 0.00041248453 | V10: =J10/$K10 -> 0.0099271277 | W10: =SUM(N10:V10) -> 1
A11: 2022 | B11: {=TRANSPOSE(classFile!I30:I38)} -> 516 | C11: 8162 | D11: 7614 | E11: 4860 | F11: 3355 | G11: 1613 | H11: 171 | I11: 4 | J11: 38 | K11: =SUM(B11:J11) -> 26333 | M11: =A11 -> 2022 | N11: =B11/$K11 -> 0.019595185 | O11: =C11/$K11 -> 0.30995329 | P11: =D11/$K11 -> 0.2891429 | Q11: =E11/$K11 -> 0.1845593 | R11: =F11/$K11 -> 0.12740668 | S11: =G11/$K11 -> 0.06125394 | T11: =H11/$K11 -> 0.0064937531 | U11: =I11/$K11 -> 0.00015190066 | V11: =J11/$K11 -> 0.0014430562 | W11: =SUM(N11:V11) -> 1
A12: 2023 | B12: {=TRANSPOSE(classFile!I44:I52)} -> 411 | C12: 8846 | D12: 8501 | E12: 6936 | F12: 4388 | G12: 2069 | H12: 515 | I12: 54 | J12: 34 | K12: =SUM(B12:J12) -> 31754 | M12: =A12 -> 2023 | N12: =B12/$K12 -> 0.012943251 | O12: =C12/$K12 -> 0.27857908 | P12: =D12/$K12 -> 0.2677143 | Q12: =E12/$K12 -> 0.21842917 | R12: =F12/$K12 -> 0.13818731 | S12: =G12/$K12 -> 0.065157146 | T12: =H12/$K12 -> 0.016218429 | U12: =I12/$K12 -> 0.0017005732 | V12: =J12/$K12 -> 0.0010707312 | W12: =SUM(N12:V12) -> 1
A13: 2024 | B13: {=TRANSPOSE(classFile!I58)} -> 87 | C13: {=TRANSPOSE(classFile!I60:I67)} -> 7854 | D13: 6452 | E13: 8531 | F13: 6621 | G13: 2534 | H13: 834 | I13: 180 | J13: 8 | K13: =SUM(B13:J13) -> 33101 | M13: =A13 -> 2024 | N13: =B13/$K13 -> 0.0026283194 | O13: =C13/$K13 -> 0.2372738 | P13: =D13/$K13 -> 0.19491858 | Q13: =E13/$K13 -> 0.25772635 | R13: =F13/$K13 -> 0.20002417 | S13: =G13/$K13 -> 0.076553578 | T13: =H13/$K13 -> 0.025195613 | U13: =I13/$K13 -> 0.0054379022 | V13: =J13/$K13 -> 0.00024168454 | W13: =SUM(N13:V13) -> 1
A14: 2025 | B14: {=TRANSPOSE(classFile!I73)} -> 3 | C14: {=TRANSPOSE(classFile!I75:I82)} -> 8612 | D14: 7790 | E14: 5489 | F14: 10206 | G14: 3889 | H14: 898 | I14: 370 | J14: 12 | K14: =SUM(B14:J14) -> 37269 | M14: =A14 -> 2025 | N14: =B14/$K14 -> 8.0495854e-05 | O14: =C14/$K14 -> 0.23107677 | P14: =D14/$K14 -> 0.2090209 | Q14: =E14/$K14 -> 0.14728058 | R14: =F14/$K14 -> 0.2738469 | S14: =G14/$K14 -> 0.10434946 | T14: =H14/$K14 -> 0.024095092 | U14: =I14/$K14 -> 0.0099278221 | V14: =J14/$K14 -> 0.00032198342 | W14: =SUM(N14:V14) -> 1

Sheet Charts
