Workbook

Sheet monthFile
A1: Year | B1: Month | C1: PeriodName | D1: Sales TY ($) | E1: Sales LY ($) | F1: Sales TY (Units) | G1: Sales LY (Units) | H1: Var LY (Units) | I1: Sales TY (ATV) | J1: Sales LY (ATV) | K1: % Margin TY | L1: % Margin LY
A2: =LEFT(C2,4) -> 2020 | B2: =RIGHT(C2,3) -> JAN | C2: 202001 - JAN | D2: 839217.08 | E2: 0 | F2: 2288 | G2: 0 | H2: 2288 | I2: 366.79068 | K2: 0.26900679
A3: =LEFT(C3,4) -> 2020 | B3: =RIGHT(C3,3) -> FEB | C3: 202002 - FEB | D3: 770072.69 | E3: 0 | F3: 2239 | G3: 0 | H3: 2239 | I3: 343.936 | K3: 0.3143633
A4: =LEFT(C4,4) -> 2020 | B4: =RIGHT(C4,3) -> MAR | C4: 202003 - MAR | D4: 922851.5 | E4: 0 | F4: 3075 | G4: 0 | H4: 3075 | I4: 300.11431 | K4: 0.2849979
A5: =LEFT(C5,4) -> Tota | B5: =RIGHT(C5,3) -> tal | C5: Total | D5: 2532141.3 | E5: 0 | F5: 7602 | G5: 0 | H5: 7602 | I5: 333.08883 | K5: 0.28862861
C7: Applied filters: Añofiscal is 2020 ENG_DIVISION is AUDIO VISUAL ENG_DEPARTMENT is VISION REGION is CAR COUNTRY is Trinidad and Tobago ENG_CLASS is not (Blank) or PREPAID BALANCE REGION is not ALL or USA COUNTRY is not Paraguay or Aruba
A9: =LEFT(C9,4) -> Peri | B9: =RIGHT(C9,3) -> ame | C9: PeriodName | D9: Sales TY ($) | E9: Sales LY ($) | F9: Sales TY (Units) | G9: Sales LY (Units) | H9: Var LY (Units) | I9: Sales TY (ATV) | J9: Sales LY (ATV) | K9: % Margin TY | L9: % Margin LY
A10: =LEFT(C10,4) -> 2020 | B10: =RIGHT(C10,3) -> APR | C10: 202004 - APR | D10: 2645.3622 | E10: 0 | F10: 5 | G10: 0 | H10: 5 | I10: 529.07244 | K10: 0.2082543
A11: =LEFT(C11,4) -> 2020 | B11: =RIGHT(C11,3) -> MAY | C11: 202005 - MAY | D11: 55084.481 | E11: 0 | F11: 109 | G11: 0 | H11: 109 | I11: 505.36221 | K11: 0.34468742
A12: =LEFT(C12,4) -> 2020 | B12: =RIGHT(C12,3) -> JUN | C12: 202006 - JUN | D12: 1087926.4 | E12: 0 | F12: 3249 | G12: 0 | H12: 3249 | I12: 334.84962 | K12: 0.26640121
A13: =LEFT(C13,4) -> 2020 | B13: =RIGHT(C13,3) -> JUL | C13: 202007 - JUL | D13: 1041346.7 | E13: 0 | F13: 3110 | G13: 0 | H13: 3110 | I13: 334.83817 | K13: 0.32110919
A14: =LEFT(C14,4) -> 2020 | B14: =RIGHT(C14,3) -> AUG | C14: 202008 - AUG | D14: 1057330.8 | E14: 0 | F14: 3305 | G14: 0 | H14: 3305 | I14: 319.91855 | K14: 0.31952675
A15: =LEFT(C15,4) -> 2020 | B15: =RIGHT(C15,3) -> SEP | C15: 202009 - SEP | D15: 843248.52 | E15: 0 | F15: 2162 | G15: 0 | H15: 2162 | I15: 390.03169 | K15: 0.28799784
A16: =LEFT(C16,4) -> 2020 | B16: =RIGHT(C16,3) -> OCT | C16: 202010 - OCT | D16: 1120041.1 | E16: 0 | F16: 2751 | G16: 0 | H16: 2751 | I16: 407.13963 | K16: 0.26397945
A17: =LEFT(C17,4) -> 2020 | B17: =RIGHT(C17,3) -> NOV | C17: 202011 - NOV | D17: 2632346.4 | E17: 0 | F17: 7712 | G17: 0 | H17: 7712 | I17: 341.33123 | K17: 0.24979803
A18: =LEFT(C18,4) -> 2020 | B18: =RIGHT(C18,3) -> DEC | C18: 202012 - DEC | D18: 2602909.2 | E18: 0 | F18: 7440 | G18: 0 | H18: 7440 | I18: 349.85339 | K18: 0.28340489
A19: =LEFT(C19,4) -> 2021 | B19: =RIGHT(C19,3) -> JAN | C19: 202101 - JAN | D19: 758888.81 | E19: 839217.08 | F19: 2333 | G19: 2288 | H19: 45 | I19: 325.28453 | J19: 366.79068 | K19: 0.36575761 | L19: 0.26900679
A20: =LEFT(C20,4) -> 2021 | B20: =RIGHT(C20,3) -> FEB | C20: 202102 - FEB | D20: 578486.44 | E20: 770072.69 | F20: 1775 | G20: 2239 | H20: -464 | I20: 325.90786 | J20: 343.936 | K20: 0.31340246 | L20: 0.3143633
A21: =LEFT(C21,4) -> 2021 | B21: =RIGHT(C21,3) -> MAR | C21: 202103 - MAR | D21: 837809.62 | E21: 922851.5 | F21: 2414 | G21: 3075 | H21: -661 | I21: 347.06281 | J21: 300.11431 | K21: 0.23083371 | L21: 0.2849979
A22: =LEFT(C22,4) -> Tota | B22: =RIGHT(C22,3) -> tal | C22: Total | D22: 12618064 | E22: 2532141.3 | F22: 36365 | G22: 7602 | H22: 28763 | I22: 346.98375 | J22: 333.08883 | K22: 0.28273839 | L22: 0.28862861
C24: Applied filters: Añofiscal is 2021 ENG_DIVISION is AUDIO VISUAL ENG_DEPARTMENT is VISION REGION is CAR COUNTRY is Trinidad and Tobago ENG_CLASS is not (Blank) or PREPAID BALANCE REGION is not ALL or USA COUNTRY is not Paraguay or Aruba
A26: =LEFT(C26,4) -> Peri | B26: =RIGHT(C26,3) -> ame | C26: PeriodName | D26: Sales TY ($) | E26: Sales LY ($) | F26: Sales TY (Units) | G26: Sales LY (Units) | H26: Var LY (Units) | I26: Sales TY (ATV) | J26: Sales LY (ATV) | K26: % Margin TY | L26: % Margin LY
A27: =LEFT(C27,4) -> 2021 | B27: =RIGHT(C27,3) -> APR | C27: 202104 - APR | D27: 821710.73 | E27: 2645.3622 | F27: 2223 | G27: 5 | H27: 2218 | I27: 369.64046 | J27: 529.07244 | K27: 0.24005116 | L27: 0.2082543
A28: =LEFT(C28,4) -> 2021 | B28: =RIGHT(C28,3) -> MAY | C28: 202105 - MAY | D28: 128608.91 | E28: 55084.481 | F28: 316 | G28: 109 | H28: 207 | I28: 406.99023 | J28: 505.36221 | K28: 0.2512827 | L28: 0.34468742
A29: =LEFT(C29,4) -> 2021 | B29: =RIGHT(C29,3) -> JUN | C29: 202106 - JUN | D29: 6499.1008 | E29: 1087926.4 | F29: 12 | G29: 3249 | H29: -3237 | I29: 541.59174 | J29: 334.84962 | K29: 0.1408949 | L29: 0.26640121
A30: =LEFT(C30,4) -> 2021 | B30: =RIGHT(C30,3) -> JUL | C30: 202107 - JUL | D30: -247.56898 | E30: 1041346.7 | F30: -1 | G30: 3110 | H30: -3111 | I30: 247.56898 | J30: 334.83817 | K30: 0.18451217 | L30: 0.32110919
A31: =LEFT(C31,4) -> 2021 | B31: =RIGHT(C31,3) -> AUG | C31: 202108 - AUG | D31: 1315158.9 | E31: 1057330.8 | F31: 3199 | G31: 3305 | H31: -106 | I31: 411.11562 | J31: 319.91855 | K31: 0.16972769 | L31: 0.31952675
A32: =LEFT(C32,4) -> 2021 | B32: =RIGHT(C32,3) -> SEP | C32: 202109 - SEP | D32: 1385471.4 | E32: 843248.52 | F32: 3224 | G32: 2162 | H32: 1062 | I32: 429.7368 | J32: 390.03169 | K32: 0.20275462 | L32: 0.28799784
A33: =LEFT(C33,4) -> 2021 | B33: =RIGHT(C33,3) -> OCT | C33: 202110 - OCT | D33: 1365228.8 | E33: 1120041.1 | F33: 2966 | G33: 2751 | H33: 215 | I33: 460.29292 | J33: 407.13963 | K33: 0.21989934 | L33: 0.26397945
A34: =LEFT(C34,4) -> 2021 | B34: =RIGHT(C34,3) -> NOV | C34: 202111 - NOV | D34: 2364961.3 | E34: 2632346.4 | F34: 4949 | G34: 7712 | H34: -2763 | I34: 477.86649 | J34: 341.33123 | K34: 0.12562161 | L34: 0.24979803
A35: =LEFT(C35,4) -> 2021 | B35: =RIGHT(C35,3) -> DEC | C35: 202112 - DEC | D35: 2448585.1 | E35: 2602909.2 | F35: 4910 | G35: 7440 | H35: -2530 | I35: 498.69351 | J35: 349.85339 | K35: 0.11435024 | L35: 0.28340489
A36: =LEFT(C36,4) -> 2022 | B36: =RIGHT(C36,3) -> JAN | C36: 202201 - JAN | D36: 694615.65 | E36: 758888.81 | F36: 1548 | G36: 2333 | H36: -785 | I36: 448.71812 | J36: 325.28453 | K36: 0.14978703 | L36: 0.36575761
A37: =LEFT(C37,4) -> 2022 | B37: =RIGHT(C37,3) -> FEB | C37: 202202 - FEB | D37: 627009.63 | E37: 578486.44 | F37: 1471 | G37: 1775 | H37: -304 | I37: 426.2472 | J37: 325.90786 | K37: 0.11135725 | L37: 0.31340246
A38: =LEFT(C38,4) -> 2022 | B38: =RIGHT(C38,3) -> MAR | C38: 202203 - MAR | D38: 716243.46 | E38: 837809.62 | F38: 1516 | G38: 2414 | H38: -898 | I38: 472.45611 | J38: 347.06281 | K38: 0.15592783 | L38: 0.23083371
A39: =LEFT(C39,4) -> Tota | B39: =RIGHT(C39,3) -> tal | C39: Total | D39: 11873845 | E39: 12618064 | F39: 26333 | G39: 36365 | H39: -10032 | I39: 450.91123 | J39: 346.98375 | K39: 0.15979808 | L39: 0.28273839
C41: Applied filters: Añofiscal is 2022 ENG_DIVISION is AUDIO VISUAL ENG_DEPARTMENT is VISION REGION is CAR COUNTRY is Trinidad and Tobago ENG_CLASS is not (Blank) or PREPAID BALANCE REGION is not ALL or USA COUNTRY is not Paraguay or Aruba
A43: =LEFT(C43,4) -> Peri | B43: =RIGHT(C43,3) -> ame | C43: PeriodName | D43: Sales TY ($) | E43: Sales LY ($) | F43: Sales TY (Units) | G43: Sales LY (Units) | H43: Var LY (Units) | I43: Sales TY (ATV) | J43: Sales LY (ATV) | K43: % Margin TY | L43: % Margin LY
A44: =LEFT(C44,4) -> 2022 | B44: =RIGHT(C44,3) -> APR | C44: 202204 - APR | D44: 682930.44 | E44: 821710.73 | F44: 1340 | G44: 2223 | H44: -883 | I44: 509.64958 | J44: 369.64046 | K44: 0.22734593 | L44: 0.24005116
A45: =LEFT(C45,4) -> 2022 | B45: =RIGHT(C45,3) -> MAY | C45: 202205 - MAY | D45: 772080.9 | E45: 128608.91 | F45: 1445 | G45: 316 | H45: 1129 | I45: 534.31204 | J45: 406.99023 | K45: 0.2087576 | L45: 0.2512827
A46: =LEFT(C46,4) -> 2022 | B46: =RIGHT(C46,3) -> JUN | C46: 202206 - JUN | D46: 1066634.4 | E46: 6499.1008 | F46: 2075 | G46: 12 | H46: 2063 | I46: 514.04068 | J46: 541.59174 | K46: 0.21467719 | L46: 0.1408949
...

Sheet Forecast
Q2: FORECAST | AF2: SEASONALITY
B3: 1 | C3: 2 | D3: 3 | E3: 4 | F3: 5 | G3: 6 | H3: 7 | I3: 8 | J3: 9 | K3: 10 | L3: 11 | M3: 12 | N3: AVG | S3: =B3 -> 1 | T3: =C3 -> 2 | U3: =D3 -> 3 | V3: =E3 -> 4 | W3: =F3 -> 5 | X3: =G3 -> 6 | Y3: =H3 -> 7 | Z3: =I3 -> 8 | ... AD3: =M3 -> 12 | AE3: AVG | AG3: 1 | AH3: 2 | AI3: 3 | AJ3: 4 | AK3: 5 | AL3: 6 | AM3: 7 | AN3: 8 | AO3: 9 | AP3: 10 | AQ3: 11 | AR3: 12
B4: April | C4: May | D4: June | E4: July | F4: August | G4: September | H4: October | I4: November | J4: December | K4: January | L4: February | M4: March | S4: =B4 -> April | T4: =C4 -> May | U4: =D4 -> June | V4: =E4 -> July | W4: =F4 -> August | X4: =G4 -> September | Y4: =H4 -> October | Z4: =I4 -> November | ... AD4: =M4 -> March | AG4: April | AH4: May | AI4: June | AJ4: July | AK4: August | AL4: September | AM4: October | AN4: November | AO4: December | AP4: January | AQ4: February | AR4: March
A5: 2020 | K5: {=TRANSPOSE(monthFile!F2:F4)} -> 2288 | L5: 2239 | M5: 3075 | N5: =AVERAGE(B5:M5) -> 2534 | Q5: Average | S5: =AVERAGE(B7:B11) -> 1477.8 | T5: =AVERAGE(C5:C11) -> 1026.3333 | U5: =AVERAGE(D5:D10) -> 1859.4 | V5: =AVERAGE(E5:E10) -> 1910 | W5: =AVERAGE(F5:F10) -> 2724.4 | X5: =AVERAGE(G5:G10) -> 2331.4 | Y5: =AVERAGE(H5:H10) -> 2989.6 | Z5: =AVERAGE(I5:I10) -> 8333.4 | AA5: =AVERAGE(J5:J10) -> 5454.6 | AB5: =AVERAGE(K5:K10) -> 1830.8333 | ... AD5: =AVERAGE(M5:M10) -> 2025 | AE5: =AVERAGE(S5:AD5) -> 2808.7444
A6: 2020 | B6: {=TRANSPOSE(monthFile!F10:F21)} -> 5 | C6: 109 | D6: 3249 | E6: 3110 | F6: 3305 | G6: 2162 | H6: 2751 | I6: 7712 | J6: 7440 | K6: 2333 | L6: 1775 | M6: 2414 | N6: =AVERAGE(B6:M6) -> 3030.4167 | Q6: Model | AF6: AVERAGE | AG6: =AVERAGE(AG8:AG13) -> 0.47294116 | AH6: =AVERAGE(AH8:AH13) -> 0.36758104 | AI6: =AVERAGE(AI8:AI13) -> 0.62407525 | AJ6: =AVERAGE(AJ8:AJ13) -> 0.64454371 | AK6: =AVERAGE(AK8:AK13) -> 0.95211764 | AL6: =AVERAGE(AL8:AL13) -> 0.86210969 | AM6: =AVERAGE(AM8:AM13) -> 1.1715309 | AN6: =AVERAGE(AN8:AN13) -> 2.9322984 | ... AP6: =AVERAGE(AP8:AP13) -> 0.6112663 | AQ6: =AVERAGE(AQ8:AQ12) -> 0.60769759 | AR6: =AVERAGE(AR8:AR12) -> 0.66860985
A7: 2021 | B7: {=TRANSPOSE(monthFile!F27:F38)} -> 2223 | C7: 316 | D7: 12 | E7: -1 | F7: 3199 | G7: 3224 | H7: 2966 | I7: 4949 | J7: 4910 | K7: 1548 | L7: 1471 | M7: 1516 | N7: =AVERAGE(B7:M7) -> 2194.4167 | Q7: WMA | R7: LY | S7: TY
A8: 2022 | B8: {=TRANSPOSE(monthFile!F44:F55)} -> 1340 | C8: 1445 | D8: 2075 | E8: 2058 | F8: 2301 | G8: 2120 | H8: 2470 | I8: 6764 | J8: 5178 | K8: 1523 | L8: 1985 | M8: 2495 | N8: =AVERAGE(B8:M8) -> 2646.1667 | R8: =1-S8 -> 0.1 | S8: 0.9 | AF8: 2020 | AG8: =B6/AVERAGE(_xlfn.ANCHORARRAY($B6)) -> 0.0016499381 | AH8: =C6/AVERAGE(_xlfn.ANCHORARRAY($B6)) -> 0.035968651 | AI8: =D6/AVERAGE(_xlfn.ANCHORARRAY($B6)) -> 1.0721298 | AJ8: =E6/AVERAGE(_xlfn.ANCHORARRAY($B6)) -> 1.0262615 | AK8: =F6/AVERAGE(_xlfn.ANCHORARRAY($B6)) -> 1.0906091 | AL8: =G6/AVERAGE(_xlfn.ANCHORARRAY($B6)) -> 0.71343325 | AM8: =H6/AVERAGE(_xlfn.ANCHORARRAY($B6)) -> 0.90779596 | AN8: =I6/AVERAGE(_xlfn.ANCHORARRAY($B6)) -> 2.5448646 | ... AR8: =M6/AVERAGE(_xlfn.ANCHORARRAY($B6)) -> 0.79659013
A9: 2023 | B9: {=TRANSPOSE(monthFile!F61:F72)} -> 1515 | C9: 1801 | D9: 1849 | E9: 1990 | F9: 1885 | G9: 1972 | H9: 2836 | I9: 8588 | J9: 5499 | K9: 1928 | L9: 1772 | M9: 1468 | N9: =AVERAGE(B9:M9) -> 2758.5833 | Q9: 2024 | S9: =AVERAGE(SUM(B8*$R$8,B9*$S$8)) -> 1497.5 | T9: =AVERAGE(SUM(C8*$R$8,C9*$S$8)) -> 1765.4 | U9: =AVERAGE(SUM(D8*$R$8,D9*$S$8)) -> 1871.6 | V9: =AVERAGE(SUM(E8*$R$8,E9*$S$8)) -> 1996.8 | W9: =AVERAGE(SUM(F8*$R$8,F9*$S$8)) -> 1926.6 | X9: =AVERAGE(SUM(G8*$R$8,G9*$S$8)) -> 1986.8 | Y9: =AVERAGE(SUM(H8*$R$8,H9*$S$8)) -> 2799.4 | Z9: =AVERAGE(SUM(I8*$R$8,I9*$S$8)) -> 8405.6 | ... AD9: =AVERAGE(SUM(M8*$R$8,M9*$S$8)) -> 1570.7 | AF9: 2021 | AG9: =B7/AVERAGE(_xlfn.ANCHORARRAY($B7)) -> 1.0130255 | AH9: =C7/AVERAGE(_xlfn.ANCHORARRAY($B7)) -> 0.14400182 | AI9: =D7/AVERAGE(_xlfn.ANCHORARRAY($B7)) -> 0.0054684237 | AJ9: =E7/AVERAGE(_xlfn.ANCHORARRAY($B7)) -> -0.00045570197 | AK9: =F7/AVERAGE(_xlfn.ANCHORARRAY($B7)) -> 1.4577906 | AL9: =G7/AVERAGE(_xlfn.ANCHORARRAY($B7)) -> 1.4691832 | AM9: =H7/AVERAGE(_xlfn.ANCHORARRAY($B7)) -> 1.351612 | AN9: =I7/AVERAGE(_xlfn.ANCHORARRAY($B7)) -> 2.2552691 | ... AR9: =M7/AVERAGE(_xlfn.ANCHORARRAY($B7)) -> 0.69084419
A10: 2024 | B10: {=TRANSPOSE(monthFile!F78:F89)} -> 1017 | C10: 1053 | D10: 2112 | E10: 2393 | F10: 2932 | G10: 2179 | H10: 3925 | I10: 13654 | J10: 4246 | K10: 1365 | L10: 1211 | M10: 1182 | N10: =AVERAGE(B10:M10) -> 3105.75 | S10: =IFERROR(ABS(B10-S9)/B10,0) -> 0.47246804 | T10: =IFERROR(ABS(C10-T9)/C10,0) -> 0.67654321 | U10: =IFERROR(ABS(D10-U9)/D10,0) -> 0.11382576 | V10: =IFERROR(ABS(E10-V9)/E10,0) -> 0.16556623 | W10: =IFERROR(ABS(F10-W9)/F10,0) -> 0.34290587 | X10: =IFERROR(ABS(G10-X9)/G10,0) -> 0.088205599 | Y10: =IFERROR(ABS(H10-Y9)/H10,0) -> 0.28677707 | Z10: =IFERROR(ABS(I10-Z9)/I10,0) -> 0.38438553 | ... AD10: =IFERROR(ABS(M10-AD9)/M10,0) -> 0.32884941 | AE10: =AVERAGE(S10:AD10) -> 0.33422451 | AF10: 2022 | AG10: =B8/AVERAGE(_xlfn.ANCHORARRAY($B8)) -> 0.5063929 | AH10: =C8/AVERAGE(_xlfn.ANCHORARRAY($B8)) -> 0.54607294 | AI10: =D8/AVERAGE(_xlfn.ANCHORARRAY($B8)) -> 0.78415318 | AJ10: =E8/AVERAGE(_xlfn.ANCHORARRAY($B8)) -> 0.77772879 | AK10: =F8/AVERAGE(_xlfn.ANCHORARRAY($B8)) -> 0.86955974 | AL10: =G8/AVERAGE(_xlfn.ANCHORARRAY($B8)) -> 0.80115891 | AM10: =H8/AVERAGE(_xlfn.ANCHORARRAY($B8)) -> 0.93342571 | AN10: =I8/AVERAGE(_xlfn.ANCHORARRAY($B8)) -> 2.5561504 | ... AR10: =M8/AVERAGE(_xlfn.ANCHORARRAY($B8)) -> 0.94287334
A11: 2025 | B11: 1294 | C11: 1434 | D11: 1566 | E11: 1682 | F11: 1963 | G11: 2272 | H11: 4543 | I11: 8024 | J11: 5229 | K11: 1407 | N11: =AVERAGE(B11:M11) -> 2941.4 | R11: =1-S11 -> 0.55 | S11: 0.45 | AF11: 2023 | AG11: =B9/AVERAGE(_xlfn.ANCHORARRAY($B9)) -> 0.54919494 | AH11: =C9/AVERAGE(_xlfn.ANCHORARRAY($B9)) -> 0.65287134 | AI11: =D9/AVERAGE(_xlfn.ANCHORARRAY($B9)) -> 0.67027158 | AJ11: =E9/AVERAGE(_xlfn.ANCHORARRAY($B9)) -> 0.72138477 | AK11: =F9/AVERAGE(_xlfn.ANCHORARRAY($B9)) -> 0.68332175 | AL11: =G9/AVERAGE(_xlfn.ANCHORARRAY($B9)) -> 0.71485968 | AM11: =H9/AVERAGE(_xlfn.ANCHORARRAY($B9)) -> 1.0280639 | AN11: =I9/AVERAGE(_xlfn.ANCHORARRAY($B9)) -> 3.1131922 | ... AR11: =M9/AVERAGE(_xlfn.ANCHORARRAY($B9)) -> 0.53215721
A12: 2026 | Q12: 2025 | S12: =AVERAGE(SUM(B9*$R$11,B10*$S$11)) -> 1290.9 | T12: =AVERAGE(SUM(C9*$R$11,C10*$S$11)) -> 1464.4 | U12: =AVERAGE(SUM(D9*$R$11,D10*$S$11)) -> 1967.35 | V12: =AVERAGE(SUM(E9*$R$11,E10*$S$11)) -> 2171.35 | W12: =AVERAGE(SUM(F9*$R$11,F10*$S$11)) -> 2356.15 | X12: =AVERAGE(SUM(G9*$R$11,G10*$S$11)) -> 2065.15 | Y12: =AVERAGE(SUM(H9*$R$11,H10*$S$11)) -> 3326.05 | Z12: =AVERAGE(SUM(I9*$R$11,I10*$S$11)) -> 10867.7 | ... AD12: =AVERAGE(SUM(M9*$R$11,M10*$S$11)) -> 1339.3 | AF12: 2024 | AG12: =B10/AVERAGE(_xlfn.ANCHORARRAY($B10)) -> 0.32745714 | AH12: =C10/AVERAGE(_xlfn.ANCHORARRAY($B$10)) -> 0.33904854 | AI12: =D10/AVERAGE(_xlfn.ANCHORARRAY($B$10)) -> 0.68002898 | AJ12: =E10/AVERAGE(_xlfn.ANCHORARRAY($B$10)) -> 0.77050632 | AK12: =F10/AVERAGE(_xlfn.ANCHORARRAY($B$10)) -> 0.94405538 | AL12: =G10/AVERAGE(_xlfn.ANCHORARRAY($B$10)) -> 0.70160187 | AM12: =H10/AVERAGE(_xlfn.ANCHORARRAY($B$10)) -> 1.2637849 | AN12: =I10/AVERAGE(_xlfn.ANCHORARRAY($B$10)) -> 4.3963616 | AO12: =J10/AVERAGE(_xlfn.ANCHORARRAY($B$10)) -> 1.3671416 | ... AR12: =M10/AVERAGE(_xlfn.ANCHORARRAY($B$10)) -> 0.3805844
S13: =IFERROR(ABS(B11-S12)/B11,0) -> 0.0023956723 | T13: =IFERROR(ABS(C11-T12)/C11,0) -> 0.021199442 | U13: =IFERROR(ABS(D11-U12)/D11,0) -> 0.25628991 | V13: =IFERROR(ABS(E11-V12)/E11,0) -> 0.29093341 | W13: =IFERROR(ABS(F11-W12)/F11,0) -> 0.20028018 | X13: =IFERROR(ABS(G11-X12)/G11,0) -> 0.091043134 | Y13: =IFERROR(ABS(H11-Y12)/H11,0) -> 0.26787365 | Z13: =IFERROR(ABS(I11-Z12)/I11,0) -> 0.3543993 | ... AB13: =IFERROR(ABS(K11-AB12)/K11,0) -> 0.19022743 | AD13: =IFERROR(ABS(M11-AD12)/M11,"") | AE13: =AVERAGE(S13:AD13) -> 0.17308384 | AF13: 2025 | AG13: =B11/AVERAGE($B$11:$M$11) -> 0.43992657 | AH13: =C11/AVERAGE($B$11:$M$11) -> 0.48752295 | AI13: =D11/AVERAGE($B$11:$M$11) -> 0.53239954 | AJ13: =E11/AVERAGE($B$11:$M$11) -> 0.57183654 | AK13: =F11/AVERAGE($B$11:$M$11) -> 0.66736928 | AL13: =G11/AVERAGE($B$11:$M$11) -> 0.7724213 | AM13: =H11/AVERAGE($B$11:$M$11) -> 1.5445026 | AN13: =I11/AVERAGE($B$11:$M$11) -> 2.7279527 | ... AR13: =M11/AVERAGE($B$11:$M$11) -> 0
AF14: 2026
Q15: 2026 | S15: =AVERAGE(SUM(B10*$R$11,B11*$S$11)) -> 1141.65 | T15: =AVERAGE(SUM(C10*$R$11,C11*$S$11)) -> 1224.45 | U15: =AVERAGE(SUM(D10*$R$11,D11*$S$11)) -> 1866.3 | V15: =AVERAGE(SUM(E10*$R$11,E11*$S$11)) -> 2073.05 | W15: =AVERAGE(SUM(F10*$R$11,F11*$S$11)) -> 2495.95 | X15: =AVERAGE(SUM(G10*$R$11,G11*$S$11)) -> 2220.85 | Y15: =AVERAGE(SUM(H10*$R$11,H11*$S$11)) -> 4203.1 | Z15: =AVERAGE(SUM(I10*$R$11,I11*$S$11)) -> 11120.5 | ... AD15: =AVERAGE(SUM(M10*$R$11,M11*$S$11)) -> 650.1
Q18: EXP SMOOTHING | S18: 0.73
Q19: 2025 | S19: =S9+($S$18*(B10-S9)) -> 1146.735 | T19: =T9+($S$18*(C10-T9)) -> 1245.348 | U19: =U9+($S$18*(D10-U9)) -> 2047.092 | V19: =V9+($S$18*(E10-V9)) -> 2286.026 | W19: =W9+($S$18*(F10-W9)) -> 2660.542 | X19: =X9+($S$18*(G10-X9)) -> 2127.106 | Y19: =Y9+($S$18*(H10-Y9)) -> 3621.088 | Z19: =Z9+($S$18*(I10-Z9)) -> 12236.932 | ... AD19: =AD9+($S$18*(M10-AD9)) -> 1286.949
S20: =IFERROR(ABS(B11-S19)/B11,0) -> 0.11380603 | T20: =IFERROR(ABS(C11-T19)/C11,0) -> 0.13155649 | U20: =IFERROR(ABS(D11-U19)/D11,0) -> 0.30721073 | V20: =IFERROR(ABS(E11-V19)/E11,0) -> 0.35911177 | W20: =IFERROR(ABS(F11-W19)/F11,0) -> 0.35534488 | X20: =IFERROR(ABS(G11-X19)/G11,0) -> 0.063773768 | Y20: =IFERROR(ABS(H11-Y19)/H11,0) -> 0.20293022 | Z20: =IFERROR(ABS(I11-Z19)/I11,0) -> 0.52504138 | ... AD20: =IFERROR(ABS(M11-AD19)/M11,0) -> 0 | AE20: =AVERAGE(S20:AB20) -> 0.22541398
S21: 0.73
Q22: 2026 | S22: =S19+($S$21*(B11-S12)) -> 1148.998 | T22: =T19+($S$21*(C11-T12)) -> 1223.156 | U22: =U19+($S$21*(D11-U12)) -> 1754.1065 | V22: =V19+($S$21*(E11-V12)) -> 1928.8005 | W22: =W19+($S$21*(F11-W12)) -> 2373.5425 | X22: =X19+($S$21*(G11-X12)) -> 2278.1065 | Y22: =Y19+($S$21*(H11-Y12)) -> 4509.4615 | Z22: =Z19+($S$21*(I11-Z12)) -> 10161.031 | ... AD22: =AD19+($S$21*(M11-AD12)) -> 309.26
S23: =IFERROR(ABS(B12-S22)/B12,0) -> 0 | T23: =IFERROR(ABS(C12-T22)/C12,0) -> 0 | U23: =IFERROR(ABS(D12-U22)/D12,0) -> 0 | V23: =IFERROR(ABS(E12-V22)/E12,0) -> 0 | W23: =IFERROR(ABS(F12-W22)/F12,0) -> 0 | X23: =IFERROR(ABS(G12-X22)/G12,0) -> 0 | Y23: =IFERROR(ABS(H12-Y22)/H12,0) -> 0 | Z23: =IFERROR(ABS(I12-Z22)/I12,0) -> 0 | ... AD23: =IFERROR(ABS(M12-AD22)/M12,0) -> 0 | AE23: =AVERAGE(S23:AD23) -> 0
Q26: SEASONALITY
Q27: 2025 | S27: =B10*AG12 -> 333.02391 | T27: =C10*AH12 -> 357.01811 | U27: =D10*AI12 -> 1436.2212 | V27: =E10*AJ12 -> 1843.8216 | W27: =F10*AK12 -> 2767.9704 | X27: =G10*AL12 -> 1528.7905 | Y27: =H10*AM12 -> 4960.3558 | Z27: =I10*AN12 -> 60027.921 | ... AD27: =M10*AR12 -> 449.85076
S29: =S12*AG12 -> 422.71442 | T29: =T12*AH12 -> 496.50268 | U29: =U12*AI12 -> 1337.855 | V29: =V12*AJ12 -> 1673.0389 | W29: =W12*AK12 -> 2224.3361 | X29: =X12*AL12 -> 1448.9131 | Y29: =Y12*AM12 -> 4203.4118 | Z29: =Z12*AN12 -> 47778.339 | ... AD29: =AD12*AR12 -> 509.71669
S31: =AVERAGE($N$5:$N$10)*AG12 -> 887.91822 | T31: =AVERAGE($N$5:$N$10)*AH12 -> 919.34895 | U31: =AVERAGE($N$5:$N$10)*AI12 -> 1843.9364 | V31: =AVERAGE($N$5:$N$10)*AJ12 -> 2089.2707 | W31: =AVERAGE($N$5:$N$10)*AK12 -> 2559.8586 | X31: =AVERAGE($N$5:$N$10)*AL12 -> 1902.4324 | Y31: =AVERAGE($N$5:$N$10)*AM12 -> 3426.823 | Z31: =AVERAGE($N$5:$N$10)*AN12 -> 11920.979 | ... AD31: =AVERAGE($N$5:$N$10)*AR12 -> 1031.9757
S33: =AVERAGE($N$5:$N$10)*AG6 -> 1282.4062 | T33: =AVERAGE($N$5:$N$10)*AH6 -> 996.71641 | U33: =AVERAGE($N$5:$N$10)*AI6 -> 1692.2147 | V33: =AVERAGE($N$5:$N$10)*AJ6 -> 1747.7161 | W33: =AVERAGE($N$5:$N$10)*AK6 -> 2581.7199 | X33: =AVERAGE($N$5:$N$10)*AL6 -> 2337.6583 | Y33: =AVERAGE($N$5:$N$10)*AM6 -> 3176.671 | Z33: =AVERAGE($N$5:$N$10)*AN6 -> 7951.09 | ... AD33: =AVERAGE($N$5:$N$10)*AR6 -> 1812.9728
S34: =IFERROR(ABS(B11-S33)/B11,0) -> 0.0089596392 | T34: =IFERROR(ABS(C11-T33)/C11,0) -> 0.30493974 | U34: =IFERROR(ABS(D11-U33)/D11,0) -> 0.080596875 | V34: =IFERROR(ABS(E11-V33)/E11,0) -> 0.039070193 | W34: =IFERROR(ABS(F11-W33)/F11,0) -> 0.31519098 | X34: =IFERROR(ABS(G11-X33)/G11,0) -> 0.028898911 | Y34: =IFERROR(ABS(H11-Y33)/H11,0) -> 0.30075478 | Z34: =IFERROR(ABS(I11-Z33)/I11,0) -> 0.0090864857 | ... AD34: =IFERROR(ABS(M11-AD33)/M11,0) -> 0 | AE34: =AVERAGE(S34:AD34) -> 0.10702461
Q36: 2026 | S36: =B11*AG13 -> 569.26498 | T36: =C11*AH13 -> 699.10791 | U36: =D11*AI13 -> 833.73768 | V36: =E11*AJ13 -> 961.82906 | W36: =F11*AK13 -> 1310.0459 | X36: =G11*AL13 -> 1754.9412 | Y36: =H11*AM13 -> 7016.6754 | Z36: =I11*AN13 -> 21889.092 | ... AD36: =M11*AR13 -> 0
S38: =S15*AG13 -> 502.24216 | T38: =T15*AH13 -> 596.94747 | U38: =U15*AI13 -> 993.61726 | V38: =V15*AJ13 -> 1185.4457 | W38: =W15*AK13 -> 1665.7204 | X38: =X15*AL13 -> 1715.4318 | Y38: =Y15*AM13 -> 6491.699 | Z38: =Z15*AN13 -> 30336.198 | ... AD38: =AD15*AR13 -> 0
S40: =AVERAGE($N$5:$N$11)*AG13 -> 1207.3303 | T40: =AVERAGE($N$5:$N$11)*AH13 -> 1337.9533 | U40: =AVERAGE($N$5:$N$11)*AI13 -> 1461.1122 | V40: =AVERAGE($N$5:$N$11)*AJ13 -> 1569.3428 | W40: =AVERAGE($N$5:$N$11)*AK13 -> 1831.5219 | X40: =AVERAGE($N$5:$N$11)*AL13 -> 2119.8256 | Y40: =AVERAGE($N$5:$N$11)*AM13 -> 4238.7183 | Z40: =AVERAGE($N$5:$N$11)*AN13 -> 7486.5673 | ... AD40: =AVERAGE($N$5:$N$11)*AR13 -> 0
S42: =AVERAGE($N$5:$N$11)*AG6 -> 1297.9352 | T42: =AVERAGE($N$5:$N$11)*AH6 -> 1008.7859 | U42: =AVERAGE($N$5:$N$11)*AI6 -> 1712.7062 | V42: =AVERAGE($N$5:$N$11)*AJ6 -> 1768.8796 | W42: =AVERAGE($N$5:$N$11)*AK6 -> 2612.9826 | X42: =AVERAGE($N$5:$N$11)*AL6 -> 2365.9656 | Y42: =AVERAGE($N$5:$N$11)*AM6 -> 3215.1381 | Z42: =AVERAGE($N$5:$N$11)*AN6 -> 8047.3718 | ... AD42: =AVERAGE($N$5:$N$11)*AR6 -> 1834.9265
S43: =IFERROR(ABS(B12-S42)/B12,0) -> 0 | T43: =IFERROR(ABS(C12-T42)/C12,0) -> 0 | U43: =IFERROR(ABS(D12-U42)/D12,0) -> 0 | V43: =IFERROR(ABS(E12-V42)/E12,0) -> 0 | W43: =IFERROR(ABS(F12-W42)/F12,0) -> 0 | X43: =IFERROR(ABS(G12-X42)/G12,0) -> 0 | Y43: =IFERROR(ABS(H12-Y42)/H12,0) -> 0 | Z43: =IFERROR(ABS(I12-Z42)/I12,0) -> 0 | ... AD43: =IFERROR(ABS(M12-AD42)/M12,0) -> 0 | AE43: =AVERAGE(S43:AD43) -> 0

Sheet Sheet1

Sheet Charts
